Workbook
Name chartTableData: #REF!
Name chartTableHeader: #REF!
Name chartTableName: #REF!
Name chartTableTotal: #REF!
Name CLS: #REF!
Name DAT: #REF!
Name filterValues: #REF!
Name phTableData: #REF!
Name phTableHeader: #REF!
Name phTableName: #REF!
Name sheetHeader: #REF!
Name statPriceChangeTableData: #REF!
Name statPriceChangeTableHeader: #REF!
Name statPriceTableData: #REF!
Name statPriceTableHeader: #REF!
Name statTableName: #REF!
Name statUpDownTableData: #REF!
Name statUpDownTableHeader: #REF!
Name statVolumeTableData: #REF!
Name statVolumeTableHeader: #REF!

Sheet DETAILS
B1: Engro Polymer & Chemicals ltd.
C6: Name | D6: Abdul Rahim Shaikh
C7: ERP | D7: 26570
C8: Financial Modeling Project # 2
C9: Class | D9: 97378
C10: Submitted to | D10: Sir Irfan Ahmed

Sheet Assumptions
A2: Engro Polymer & Chemicals ltd.
C6: Historical Data (000s) | H6: Forecasted Data (000s)
B7: Assumptions | C7: 2019 | D7: 2020 | E7: 2021 | F7: 2022 | G7: 2023 | H7: 2024 | I7: 2025 | J7: 2026 | K7: 2027 | L7: 2028
A8: Property Plant and equipment | C8: =SUM(C9:C11) -> 31064266 | D8: =SUM(D9:D11) -> 36186640 | E8: =SUM(E9:E11) -> 36792644 | F8: 41004218 | G8: 44794643 | H8: ='Depreciation schedule'!H2 -> 50177016 | I8: ='Depreciation schedule'!I2 -> 52227831 | J8: ='Depreciation schedule'!J2 -> 54002526 | K8: ='Depreciation schedule'!K2 -> 59152246 | L8: ='Depreciation schedule'!L2 -> 61423110
A9: Operating assets | C9: 18304481 | D9: 19285257 | E9: 31388709 | F9: 34375626 | G9: 34567240 | H9: ='Depreciation schedule'!H3 -> 38184094 | I9: ='Depreciation schedule'!I3 -> 41009356 | J9: ='Depreciation schedule'!J3 -> 44477084 | K9: ='Depreciation schedule'!K3 -> 48906953 | L9: ='Depreciation schedule'!L3 -> 50373110
A10: Capital work in progress | C10: 12695993 | D10: 16837591 | E10: 5185100 | F10: 6416479 | G10: 9981976 | H10: ='Depreciation schedule'!H4 -> 11832130 | I10: ='Depreciation schedule'!I4 -> 11038283 | J10: ='Depreciation schedule'!J4 -> 9321969.9 | K10: ='Depreciation schedule'!K4 -> 10044894 | L10: ='Depreciation schedule'!L4 -> 10851944
A11: Capital Spares | B11: Moving average | C11: 63792 | D11: 63792 | E11: 218835 | F11: 212113 | G11: 245427 | H11: ='Depreciation schedule'!H5 -> 160791.8 | I11: ='Depreciation schedule'!I5 -> 180191.76 | J11: ='Depreciation schedule'!J5 -> 203471.71 | K11: ='Depreciation schedule'!K5 -> 200399.05 | L11: ='Depreciation schedule'!L5 -> 198056.27
A14: Operating Assets
A15: Leasehold land
A16: Gross carrying value - As at January 1,(Current Year) | B16: Depreciation schedule
A17: Cost | C17: 194127 | D17: 1133655 | E17: 1152179 | F17: 1152179 | G17: 1152179 | H17: ='Depreciation schedule'!H9 -> 1175179 | I17: ='Depreciation schedule'!I9 -> 1175179 | J17: ='Depreciation schedule'!J9 -> 1175179 | K17: ='Depreciation schedule'!K9 -> 1198638.1 | L17: ='Depreciation schedule'!L9 -> 1198638.1
A18: Accumulated depreciation | C18: -52666 | D18: -85617 | E18: -124589 | F18: -164047 | G18: -203504 | H18: ='Depreciation schedule'!H10 -> -243412 | I18: ='Depreciation schedule'!I10 -> -282269.1 | J18: ='Depreciation schedule'!J10 -> -321126.2 | K18: ='Depreciation schedule'!K10 -> -359983.3 | L18: ='Depreciation schedule'!L10 -> -399616.07
A19: Net book value | C19: =SUM(C17:C18) -> 141461 | D19: =SUM(D17:D18) -> 1048038 | E19: =SUM(E17:E18) -> 1027590 | F19: 988132 | G19: 948675 | H19: ='Depreciation schedule'!H11 -> 931767 | I19: ='Depreciation schedule'!I11 -> 892909.9 | J19: ='Depreciation schedule'!J11 -> 854052.8 | K19: ='Depreciation schedule'!K11 -> 838654.83 | L19: ='Depreciation schedule'!L11 -> 799022.06
A20: Year ended December 31, Current | H20: ='Depreciation schedule'!H12 -> 0 | I20: ='Depreciation schedule'!I12 -> 0 | J20: ='Depreciation schedule'!J12 -> 0 | K20: ='Depreciation schedule'!K12 -> 0 | L20: ='Depreciation schedule'!L12 -> 0
A21: Net carrying value | H21: ='Depreciation schedule'!H13 -> 0 | I21: ='Depreciation schedule'!I13 -> 0 | J21: ='Depreciation schedule'!J13 -> 0 | K21: ='Depreciation schedule'!K13 -> 0 | L21: ='Depreciation schedule'!L13 -> 0
A22: Opening net book value | C22: =C19 -> 141461 | D22: 1048038 | E22: =E19 -> 1027590 | F22: 988132 | G22: 948675 | H22: ='Depreciation schedule'!H14 -> 931767 | I22: ='Depreciation schedule'!I14 -> 892909.9 | J22: ='Depreciation schedule'!J14 -> 854052.8 | K22: ='Depreciation schedule'!K14 -> 838654.83 | L22: ='Depreciation schedule'!L14 -> 799022.06
A23: Additions | C23: 939528 | D23: 18524 | G23: 23000 | H23: ='Depreciation schedule'!H15 -> 0 | I23: ='Depreciation schedule'!I15 -> 0 | J23: ='Depreciation schedule'!J15 -> 23459.13 | K23: ='Depreciation schedule'!K15 -> 0 | L23: ='Depreciation schedule'!L15 -> 0
A24: Disposals / write-offs | D24: - | G24: - | H24: ='Depreciation schedule'!H16 -> 0 | I24: ='Depreciation schedule'!I16 -> 0 | J24: ='Depreciation schedule'!J16 -> 0 | K24: ='Depreciation schedule'!K16 -> 0 | L24: ='Depreciation schedule'!L16 -> 0
A25: Cost | C25: 0 | D25: 0 | E25: 0 | F25: 0 | G25: 0 | H25: 0 | I25: 0 | J25: ='Depreciation schedule'!J17 -> 0 | K25: ='Depreciation schedule'!K17 -> 0 | L25: ='Depreciation schedule'!L17 -> 0
A26: Accumulated depreciation | D26: - | G26: - | H26: ='Depreciation schedule'!H18 -> 0 | I26: ='Depreciation schedule'!I18 -> 0 | J26: ='Depreciation schedule'!J18 -> 0 | K26: ='Depreciation schedule'!K18 -> 0 | L26: ='Depreciation schedule'!L18 -> 0
A27: Depreciation charge | C27: -32931 | D27: -38972 | E27: -39458 | F27: -39457 | G27: -39908 | H27: ='Depreciation schedule'!H19 -> -38857.098 | I27: ='Depreciation schedule'!I19 -> -38857.098 | J27: ='Depreciation schedule'!J19 -> -38857.098 | K27: ='Depreciation schedule'!K19 -> -39632.771 | L27: ='Depreciation schedule'!L19 -> -39632.771
A28: Net book value | C28: =SUM(C22:C27) -> 1048058 | D28: =SUM(D22:D27) -> 1027590 | E28: =SUM(E22:E27) -> 988132 | F28: 948675 | G28: 931767 | H28: ='Depreciation schedule'!H20 -> 892909.9 | I28: ='Depreciation schedule'!I20 -> 854052.8 | J28: ='Depreciation schedule'!J20 -> 838654.83 | K28: ='Depreciation schedule'!K20 -> 799022.06 | L28: ='Depreciation schedule'!L20 -> 759389.29
A29: Gross carrying value - As at December 31, Current Year | H29: ='Depreciation schedule'!H21 -> 0 | I29: ='Depreciation schedule'!I21 -> 0 | J29: ='Depreciation schedule'!J21 -> 0 | K29: ='Depreciation schedule'!K21 -> 0 | L29: ='Depreciation schedule'!L21 -> 0
A30: Cost | C30: 1133655 | D30: 1152179 | E30: 1152179 | F30: 1152179 | G30: 1175179 | H30: ='Depreciation schedule'!H22 -> 1175179 | I30: ='Depreciation schedule'!I22 -> 1175179 | J30: ='Depreciation schedule'!J22 -> 1198638.1 | K30: ='Depreciation schedule'!K22 -> 1198638.1 | L30: ='Depreciation schedule'!L22 -> 1198638.1
A31: Accumulated depreciation | C31: -85617 | D31: -124589 | E31: -164047 | F31: -203504 | G31: -243412 | H31: ='Depreciation schedule'!H23 -> -282269.1 | I31: ='Depreciation schedule'!I23 -> -321126.2 | J31: ='Depreciation schedule'!J23 -> -359983.3 | K31: ='Depreciation schedule'!K23 -> -399616.07 | L31: ='Depreciation schedule'!L23 -> -439248.84
A32: Net book value | C32: =SUM(C30:C31) -> 1048038 | D32: =SUM(D30:D31) -> 1027590 | E32: =SUM(E30:E31) -> 988132 | F32: 948675 | G32: 931767 | H32: ='Depreciation schedule'!H24 -> 892909.9 | I32: ='Depreciation schedule'!I24 -> 854052.8 | J32: ='Depreciation schedule'!J24 -> 838654.83 | K32: ='Depreciation schedule'!K24 -> 799022.06 | L32: ='Depreciation schedule'!L24 -> 759389.29
A35: Buildings on leasehold land
A36: Gross carrying value - As at January 1,(Current Year) | B36: Depreciation Schedule
A37: Cost | C37: 552959 | D37: 551560 | E37: 608098 | F37: 1253027 | G37: 1212885 | H37: ='Depreciation schedule'!H29 -> 1299054 | I37: ='Depreciation schedule'!I29 -> 2676788.5 | J37: ='Depreciation schedule'!J29 -> 2577736.1 | K37: ='Depreciation schedule'!K29 -> 2760870.4 | L37: ='Depreciation schedule'!L29 -> 5688960
A38: Accumulated depreciation | C38: -169358 | D38: -198464 | E38: -222189 | F38: -266271 | G38: -252888 | H38: ='Depreciation schedule'!H30 -> -309378 | I38: ='Depreciation schedule'!I30 -> -360913.32 | J38: ='Depreciation schedule'!J30 -> -467105.34 | K38: ='Depreciation schedule'!K30 -> -569367.8 | L38: ='Depreciation schedule'!L30 -> -678895.47
A39: Net book value | C39: =SUM(C37:C38) -> 383601 | D39: =SUM(D37:D38) -> 353096 | E39: =SUM(E37:E38) -> 385909 | F39: 986756 | G39: 959997 | H39: ='Depreciation schedule'!H31 -> 989676 | I39: ='Depreciation schedule'!I31 -> 2315875.2 | J39: ='Depreciation schedule'!J31 -> 2110630.7 | K39: ='Depreciation schedule'!K31 -> 2191502.6 | L39: ='Depreciation schedule'!L31 -> 5010064.5
A40: Year ended December 31, Current | H40: ='Depreciation schedule'!H32 -> 0 | I40: ='Depreciation schedule'!I32 -> 0 | J40: ='Depreciation schedule'!J32 -> 0 | K40: ='Depreciation schedule'!K32 -> 0 | L40: ='Depreciation schedule'!L32 -> 0
A41: Net carrying value | H41: ='Depreciation schedule'!H33 -> 0 | I41: ='Depreciation schedule'!I33 -> 0 | J41: ='Depreciation schedule'!J33 -> 0 | K41: ='Depreciation schedule'!K33 -> 0 | L41: ='Depreciation schedule'!L33 -> 0
A42: Opening net book value | C42: =C39 -> 383601 | D42: 353096 | E42: =E39 -> 385909 | F42: 986756 | G42: 959997 | H42: ='Depreciation schedule'!H34 -> 989676 | I42: ='Depreciation schedule'!I34 -> 2315875.2 | J42: ='Depreciation schedule'!J34 -> 2110630.7 | K42: ='Depreciation schedule'!K34 -> 2191502.6 | L42: ='Depreciation schedule'!L34 -> 5010064.5
A43: Additions | C43: 1980 | D43: 56538 | E43: 644929 | F43: 22975 | G43: 86169 | H43: ='Depreciation schedule'!H35 -> 1377734.5 | I43: ='Depreciation schedule'!I35 -> 49080.519 | J43: ='Depreciation schedule'!J35 -> 183134.38 | K43: ='Depreciation schedule'!K35 -> 2928089.6 | L43: ='Depreciation schedule'!L35 -> 104310.49
A44: Disposals / write-offs | D44: - | F44: -63117 | G44: - | H44: ='Depreciation schedule'!H36 -> 0 | I44: ='Depreciation schedule'!I36 -> 0 | J44: ='Depreciation schedule'!J36 -> 0 | K44: ='Depreciation schedule'!K36 -> 0 | L44: ='Depreciation schedule'!L36 -> 0
A45: Cost | C45: -3379 | D45: 0 | E45: 0 | F45: 63117 | G45: 0 | H45: 0 | I45: ='Depreciation schedule'!I37 -> -148132.97 | J45: ='Depreciation schedule'!J37 -> 0 | K45: ='Depreciation schedule'!K37 -> 0 | L45: ='Depreciation schedule'!L37 -> -320464.47
A46: Accumulated depreciation | C46: 596 | D46: - | F46: - | G46: - | H46: ='Depreciation schedule'!H38 -> 0 | I46: ='Depreciation schedule'!I38 -> 148132.97 | J46: ='Depreciation schedule'!J38 -> 0 | K46: ='Depreciation schedule'!K38 -> 0 | L46: ='Depreciation schedule'!L38 -> 320464.47
A47: Depreciation charge | C47: -29702 | D47: -23725 | E47: -44082 | F47: -49734 | G47: -56490 | H47: ='Depreciation schedule'!H39 -> -51535.324 | I47: ='Depreciation schedule'!I39 -> -106192.02 | J47: ='Depreciation schedule'!J39 -> -102262.46 | K47: ='Depreciation schedule'!K39 -> -109527.67 | L47: ='Depreciation schedule'!L39 -> -225689.15
A48: Net book value | C48: =SUM(C42:C47) -> 353096 | D48: 385909 | E48: =SUM(E42:E47) -> 986756 | F48: 959997 | G48: 989676 | H48: ='Depreciation schedule'!H40 -> 2315875.2 | I48: ='Depreciation schedule'!I40 -> 2258763.7 | J48: ='Depreciation schedule'!J40 -> 2191502.6 | K48: ='Depreciation schedule'!K40 -> 5010064.5 | L48: ='Depreciation schedule'!L40 -> 4888685.9
...

Sheet Valuation
B2: Engro Polymer & Chemicals ltd.
E5: Valuation
D8: 2024 | E8: 2025 | F8: 2026 | G8: 2027 | H8: 2028
D9: Rs(000) | E9: Rs(000) | F9: Rs(000) | G9: Rs(000) | H9: Rs(000) | J9: Factors | K9: Basis
C10: Period | D10: 1 | E10: 2 | F10: 3 | G10: 4 | H10: 5 | J10: Risk Free Rate | K10: 10 Year Government bond yeild | L10: 0.11852
C11: Debt | D11: ='Balance Sheet'!G35+'Balance Sheet'!H47 -> 43664347 | E11: ='Balance Sheet'!H35+'Balance Sheet'!I47 -> 60106613 | F11: ='Balance Sheet'!I35+'Balance Sheet'!J47 -> 1.2645715e+08 | G11: ='Balance Sheet'!J35+'Balance Sheet'!K47 -> 2.1803872e+08 | H11: ='Balance Sheet'!K35+'Balance Sheet'!L47 -> 10950371 | J11: Beta of Stock | K11: 5 year Beta from Refinitiv | L11: 0.77
C12: Equity | D12: ='Balance Sheet'!G33 -> 38109301 | E12: ='Balance Sheet'!H33 -> 46862222 | F12: ='Balance Sheet'!I33 -> 56980553 | G12: ='Balance Sheet'!J33 -> 68640679 | H12: ='Balance Sheet'!K33 -> 83908292 | J12: Market return | K12: KSE 100 | L12: ='KSE-100 data'!F5 -> 0.20870359
C13: Debt+Equity | D13: =D11+D12 -> 81773648 | E13: =E11+E12 -> 1.0696884e+08 | F13: =F11+F12 -> 1.8343771e+08 | G13: =G11+G12 -> 2.866794e+08 | H13: =H11+H12 -> 94858664 | J13: Cost of equity | K13: CAPM | L13: =L10+(L12*L11) -> 0.27922177
C14: Weight of Debt | D14: =D11/D13 -> 0.53396599 | E14: =E11/E13 -> 0.56190771 | F14: =F11/F13 -> 0.68937383 | G14: =G11/G13 -> 0.76056641 | H14: =H11/H13 -> 0.11543881 | J14: Cost of Debt | K14: Average of all debt | L14: =AVERAGE(AVERAGE('Loan Schedule'!F11:K11)+AVERAGE('Loan Schedule'!F33:K33)+AVERAGE('Loan Schedule'!F55:AS55)+AVERAGE('Loan Schedule'!F79:M79)+AVERAGE('Loan Schedule'!F104:Q104)+AVERAGE('Loan Schedule'!F128:U128)+AVERAGE('Loan Schedule'!F152:L152)+AVERAGE('Loan Schedule'!F182:AK182)+AVERAGE('Loan Schedule'!F208:AJ208)) -> 0.28886749
C15: Weight of Equity | D15: =D12/D13 -> 0.46603401 | E15: =E12/E13 -> 0.43809229 | F15: =F12/F13 -> 0.31062617 | G15: =G12/G13 -> 0.23943359 | H15: =H12/H13 -> 0.88456119 | J15: Tax Rate | K15: Asumptions | L15: 0.29
C16: Tax Rate | D16: =Assumptions!H575 -> 0.29 | E16: =Assumptions!I575 -> 0.29 | F16: =Assumptions!J575 -> 0.29 | G16: =Assumptions!K575 -> 0.29 | H16: =Assumptions!L575 -> 0.29 | J16: Sustainable Growth Rate | K16: GDP growth | L16: =AVERAGE(Regression!E11:E15) -> 0.03564
C17: wd(rd)(1-T) | D17: =D14*$L$14*(1-D16) -> 0.10951425 | E17: =E14*$L$14*(1-E16) -> 0.11524498 | F17: =F14*$L$14*(1-F16) -> 0.14138776 | G17: =G14*$L$14*(1-G16) -> 0.15598907 | H17: =H14*$L$14*(1-H16) -> 0.02367603
C18: ws(rs) | D18: =D15*$L$13 -> 0.13012684 | E18: =E15*$L$13 -> 0.1223249 | F18: =F15*$L$13 -> 0.086733589 | G18: =G15*$L$13 -> 0.06685507 | H18: =H15*$L$13 -> 0.24698874
C19: Weighted Average Cost Of Capital (WACC) | D19: =D17+D18 -> 0.23964109 | E19: =E17+E18 -> 0.23756988 | F19: =F17+F18 -> 0.22812135 | G19: =G17+G18 -> 0.22284414 | H19: =H17+H18 -> 0.27066477
C21: Cashflow from Operations | D21: =CashFlow!G12 -> 28253790 | E21: =CashFlow!H12 -> 16349597 | F21: =CashFlow!I12 -> 17395952 | G21: =CashFlow!J12 -> 20425307 | H21: =CashFlow!K12 -> 23847857
C22: Add Interest (Tax Adjusted) | D22: =-'Income Statement'!G15*(1-Valuation!$L$15) -> 854626.17 | E22: =-'Income Statement'!H15*(1-Valuation!$L$15) -> 700912.51 | F22: =-'Income Statement'!I15*(1-Valuation!$L$15) -> 861906 | G22: =-'Income Statement'!J15*(1-Valuation!$L$15) -> 746997.3 | H22: =-'Income Statement'!K15*(1-Valuation!$L$15) -> 822023.95
C23: Less Capex | D23: =CashFlow!G15+CashFlow!G17+CashFlow!G18 -> -11092190 | E23: =CashFlow!H15+CashFlow!H17+CashFlow!H18 -> -10406050 | F23: =CashFlow!I15+CashFlow!I17+CashFlow!I18 -> -11529927 | G23: =CashFlow!J15+CashFlow!J17+CashFlow!J18 -> -12920824 | H23: =CashFlow!K15+CashFlow!K17+CashFlow!K18 -> -9868883.5
C24: Free Cashflow to Firm | D24: =SUM(D21:D23) -> 18016226 | E24: =SUM(E21:E23) -> 6644459.6 | F24: =SUM(F21:F23) -> 6727931 | G24: =SUM(G21:G23) -> 8251480.2 | H24: =SUM(H21:H23) -> 14800997
C25: Discounted Cashflows | D25: =D24 -> 18016226 | E25: =E24/((1+E19)^D10) -> 5368957.1 | F25: =F24/((1+F19)^E10) -> 4460658.4 | G25: =G24/((1+G19)^F10) -> 4512513.8 | H25: =H24/((1+H19)^G10) -> 5677629.3
C27: Net Present Value | D27: =SUM(D25:H25) -> 38035985
C28: Terminal Value | D28: =((H24*(1+L16))/(H19-L16))/((1+H19)^(H8-D8)) -> 25018555
C30: Value of Firm | D30: =SUM(D27:D28) -> 63054539
C31: No. Of Shares | D31: ='IS Assumptions'!$G$156 -> 908923
C32: Value per Share | D32: =D30/D31 -> 69.372806
C35: Current Value per Share | D35: 38.12 | E35: PSX Share Price
C37: Decision | D37: =IF(D35<D32,"Buy","Sell") -> Buy
C39: "Based on Forecasted Cashflows of 5 years we see that Share price is Undervalued today as the Value per share (by discounting future Cashflows) is higher than Actual Share Price today. We can therefore, Invest in Engro Polymers and Chemicals shares TODAY!"

Sheet Balance Sheet
A1: Engro Polymer & Chemicals ltd.
B4: Historical Data (000s) | G4: Forecasted Data (000s)
A5: Balance Sheet | B5: 2019 | C5: 2020 | D5: 2021 | E5: 2022 | F5: 2023 | G5: 2024 | H5: 2025 | I5: 2026 | J5: 2027 | K5: 2028
A6: Assets
A7: Non Current Assets
A8: Property, Plant and Equipment | B8: =Assumptions!C8 -> 31064266 | C8: =Assumptions!D8 -> 36186640 | D8: =Assumptions!E8 -> 36792644 | E8: =Assumptions!F8 -> 41004218 | F8: =Assumptions!G8 -> 44794643 | G8: =Assumptions!H8 -> 50177016 | H8: =Assumptions!I8 -> 52227831 | I8: =Assumptions!J8 -> 54002526 | ... K8: =Assumptions!L8 -> 61423110
A9: Right of Use Asset | B9: =Assumptions!C149 -> 2747801 | C9: =Assumptions!D149 -> 2305604 | D9: =Assumptions!E149 -> 2036649 | E9: =Assumptions!F149 -> 1617227 | F9: =Assumptions!G149 -> 1156505 | G9: =Assumptions!H149 -> 950402.01 | H9: =Assumptions!I149 -> 676888.89 | I9: =Assumptions!J149 -> 406866.79 | ... K9: =Assumptions!L149 -> 144142.88
A10: Intangible asstes | B10: =Assumptions!C214 -> 78966 | C10: =Assumptions!D214 -> 101971 | D10: =Assumptions!E214 -> 711832 | E10: =Assumptions!F214 -> 686598 | F10: =Assumptions!G214 -> 620205 | G10: =Assumptions!H214 -> 702765.81 | H10: =Assumptions!I214 -> 833378.49 | I10: =Assumptions!J214 -> 985512.7 | ... K10: =Assumptions!L214 -> 1085083.9
A11: Long Term Invetsments | B11: =Assumptions!C223 -> 1625000 | C11: =Assumptions!D223 -> 1625000 | D11: =Assumptions!E223 -> 2465000 | E11: =Assumptions!F223 -> 3884000 | F11: =Assumptions!G223 -> 6837000 | G11: =Assumptions!H223 -> 6837000 | H11: =Assumptions!I223 -> 6837000 | I11: =Assumptions!J223 -> 6837000 | ... K11: =Assumptions!L223 -> 6837000
A12: Investments in Amortised Cost | B12: =Assumptions!C237 -> 5421150 | C12: =Assumptions!D237 -> 4660833 | D12: =Assumptions!E237 -> 3092784 | E12: =Assumptions!F237 -> 1317508 | F12: =Assumptions!G237 -> 0 | G12: =Assumptions!H238 -> 0 | H12: =Assumptions!I238 -> 0 | I12: =Assumptions!J238 -> 0 | J12: =Assumptions!K238 -> 0 | K12: =Assumptions!L238 -> 0
A13: Long term loans and Advance | B13: =Assumptions!C245 -> 72078 | C13: =Assumptions!D245 -> 29286 | D13: =Assumptions!E245 -> 674 | E13: =Assumptions!F245 -> 0 | F13: =Assumptions!G245 -> 21837 | G13: =Assumptions!H245 -> 43152.386 | H13: =Assumptions!I245 -> 16852.605 | I13: =Assumptions!J245 -> 12387.009 | ... K13: =Assumptions!L245 -> 28608.561
A14: Deferred Tax Asset | B14: =Assumptions!C247 -> 114510 | C14: =Assumptions!D247 -> 0 | D14: =Assumptions!E247 -> 0 | E14: =Assumptions!F247 -> 0 | F14: =Assumptions!G247 -> 0 | G14: =Assumptions!H247 -> 0 | H14: =Assumptions!I247 -> 0 | I14: =Assumptions!J247 -> 0 | ... K14: =Assumptions!L247 -> 0
B15: =SUM(B8:B14) -> 41123771 | C15: =SUM(C8:C13) -> 44909334 | D15: =SUM(D8:D13) -> 45099583 | E15: =SUM(E8:E13) -> 48509551 | F15: =SUM(F8:F13) -> 53430190 | G15: =SUM(G8:G13) -> 58710336 | H15: =SUM(H8:H13) -> 60591951 | I15: =SUM(I8:I13) -> 62244292 | J15: =SUM(J8:J13) -> 67103479 | K15: =SUM(K8:K13) -> 69517945
A16: Current Assets
A17: Stores, spares and loose tools | B17: =Assumptions!C253 -> 1678013 | C17: =Assumptions!D253 -> 1784734 | D17: =Assumptions!E253 -> 2041839 | E17: =Assumptions!F253 -> 2464113 | F17: =Assumptions!G253 -> 3311772 | G17: =Assumptions!H253 -> 2256094.2 | H17: =Assumptions!I253 -> 2306313.1 | I17: =Assumptions!J253 -> 2287272.7 | ... K17: =Assumptions!L253 -> 1881284.4
A18: Stock-in-trade | B18: =Assumptions!C259 -> 4350059 | C18: =Assumptions!D259 -> 6194509 | D18: =Assumptions!E259 -> 12590666 | E18: =Assumptions!F259 -> 10415992 | F18: =Assumptions!G259 -> 16620634 | G18: =Assumptions!H259 -> 12666611 | H18: =Assumptions!I259 -> 12365472 | I18: =Assumptions!J259 -> 14055210 | ... K18: =Assumptions!L259 -> 17114865
A19: Trade debts | B19: =Assumptions!C271 -> 469613 | C19: =Assumptions!D271 -> 586212 | D19: =Assumptions!E271 -> 834355 | E19: =Assumptions!F271 -> 2676464 | F19: =Assumptions!G271 -> 1612111 | G19: =Assumptions!H271 -> 1527824.5 | H19: =Assumptions!I271 -> 1486656.8 | I19: =Assumptions!J271 -> 1687888.3 | ... K19: =Assumptions!L271 -> 2102358.9
A20: Income tax payments less provision | B20: =Assumptions!C273 -> 88886 | C20: =Assumptions!D273 -> 159818 | D20: =Assumptions!E273 -> - | E20: =Assumptions!F273 -> 0 | F20: =Assumptions!G273 -> 0 | G20: =Assumptions!H273 -> 0 | H20: =Assumptions!I273 -> 0 | I20: =Assumptions!J273 -> 0 | ... K20: =Assumptions!L273 -> 0
A21: Loans, advances, deposits, prepayments and other receivables | B21: =Assumptions!C297 -> 936207 | C21: =Assumptions!D297 -> 310892 | D21: =Assumptions!E297 -> 1507325 | E21: =Assumptions!F297 -> 2980140 | F21: =Assumptions!G297 -> 5817368 | G21: =Assumptions!H297 -> 2814703.7 | H21: =Assumptions!I297 -> 2817698.4 | I21: =Assumptions!J297 -> 3280970.3 | ... K21: =Assumptions!L297 -> 4152107.1
A22: Short Term Investments | B22: =Assumptions!C308 -> 8042074 | C22: =Assumptions!D308 -> 14144693 | D22: =Assumptions!E308 -> 13830849 | E22: =Assumptions!F308 -> 14059319 | F22: =Assumptions!G308 -> 3345457 | G22: =Assumptions!H308 -> 8244967.7 | H22: =Assumptions!I308 -> 7078577.6 | I22: =Assumptions!J308 -> 5659224.7 | ... K22: =Assumptions!L308 -> 6577353
A23: Cash and bank balances | B23: =Assumptions!C315 -> 777823 | C23: =Assumptions!D315 -> 940920 | D23: =Assumptions!E315 -> 1916986 | E23: =Assumptions!F315 -> 2852045 | F23: =Assumptions!G315 -> 3985495 | G23: =Assumptions!H620 -> 14202304 | H23: =Assumptions!I620 -> 30123805 | I23: =Assumptions!J620 -> 57640395 | J23: =Assumptions!K620 -> 1.3105083e+08 | K23: =Assumptions!L620 -> 2.362844e+08
B24: =SUM(B17:B23) -> 16342675 | C24: =SUM(C17:C23) -> 24121778 | D24: =SUM(D17:D23) -> 32722020 | E24: =SUM(E17:E23) -> 35448073 | F24: =SUM(F17:F23) -> 34692837 | G24: =SUM(G17:G23) -> 41712505 | H24: =SUM(H17:H23) -> 56178523 | I24: =SUM(I17:I23) -> 84610961 | ... K24: =SUM(K17:K23) -> 2.6811237e+08
A25: Total Assets | B25: =B15+B24 -> 57466446 | C25: =C15+C24 -> 69031112 | D25: =D15+D24 -> 77821603 | E25: =E15+E24 -> 83957624 | F25: =F15+F24 -> 88123027 | G25: =G15+G24 -> 1.0042284e+08 | H25: =H15+H24 -> 1.1677047e+08 | I25: =I15+I24 -> 1.4685525e+08 | ... K25: =K15+K24 -> 3.3763031e+08
A27: Equity and Liabilities
A28: Equity
A29: Ordinary share capital | B29: =Assumptions!C325 -> 9089233 | C29: =Assumptions!D325 -> 9089233 | D29: =Assumptions!E325 -> 9089233 | E29: =Assumptions!F325 -> 9089233 | F29: =Assumptions!G325 -> 9089233 | G29: =Assumptions!H325 -> 9089233 | H29: =Assumptions!I325 -> 9089233 | I29: =Assumptions!J325 -> 9089233 | ... K29: =Assumptions!L325 -> 9089233
A30: Preference shares | B30: =Assumptions!C332 -> 0 | C30: =Assumptions!D332 -> 3000000 | D30: =Assumptions!E332 -> 3000000 | E30: =Assumptions!F332 -> 3000000 | F30: =Assumptions!G332 -> 3000000 | G30: =Assumptions!H332 -> 3000000 | H30: =Assumptions!I332 -> 3000000 | I30: =Assumptions!J332 -> 3000000 | ... K30: =Assumptions!L332 -> 3000000
A31: share premium | B31: =Assumptions!C334 -> 3874953 | C31: =Assumptions!D334 -> 3874953 | D31: =Assumptions!E334 -> 3874953 | E31: =Assumptions!F334 -> 3874953 | F31: =Assumptions!G334 -> 3874953 | G31: =Assumptions!H334 -> 3874953 | H31: =Assumptions!I334 -> 3874953 | I31: =Assumptions!J334 -> 3874953 | ... K31: =Assumptions!L334 -> 3874953
A32: Unappropriated profits | B32: =Assumptions!C336 -> 4766837 | C32: =Assumptions!D336 -> 10106711 | D32: =Assumptions!E336 -> 13994903 | E32: =Assumptions!F336 -> 11169486 | F32: =Assumptions!G336 -> 12938222 | G32: =F32+'Income Statement'!G21 -> 22145115 | H32: =G32+'Income Statement'!H21 -> 30898036 | I32: =H32+'Income Statement'!I21 -> 41016367 | J32: =I32+'Income Statement'!J21 -> 52676493 | K32: =J32+'Income Statement'!K21 -> 67944106
B33: =SUM(B29:B32) -> 17731023 | C33: =SUM(C29:C32) -> 26070897 | D33: =SUM(D29:D32) -> 29959089 | E33: =SUM(E29:E32) -> 27133672 | F33: =SUM(F29:F32) -> 28902408 | G33: =SUM(G29:G32) -> 38109301 | H33: =SUM(H29:H32) -> 46862222 | I33: =SUM(I29:I32) -> 56980553 | ... K33: =SUM(K29:K32) -> 83908292
A34: Non Current Liabilities
A35: Long Term Borrowings | B35: =Assumptions!C359 -> 19388880 | C35: =Assumptions!D359 -> 19790152 | D35: =Assumptions!E359 -> 17081828 | E35: =Assumptions!F359 -> 19329365 | F35: =Assumptions!G359 -> 20927785 | G35: =SUM('Loan Schedule'!J224:M224) -> 18197359 | H35: =SUM('Loan Schedule'!K224:N224) -> 16829349 | I35: =SUM('Loan Schedule'!L224:O224) -> 16513141 | J35: =SUM('Loan Schedule'!M224:P224) -> 13259002 | K35: =SUM('Loan Schedule'!N224:Q224) -> 10950371
A36: Government Grant | B36: =Assumptions!C367 -> 0 | C36: =Assumptions!D367 -> 0 | D36: =Assumptions!E367 -> 146227 | E36: =Assumptions!F367 -> 184609 | F36: =Assumptions!G367 -> 195232 | G36: =Assumptions!H367 -> 349431.83 | H36: =Assumptions!I367 -> 386883.36 | I36: =Assumptions!J367 -> 454145.88 | ... K36: =Assumptions!L367 -> 618129.4
A37: Lease liabilities | B37: =Assumptions!C372 -> 4543830 | C37: =Assumptions!D372 -> 3614312 | D37: =Assumptions!E372 -> 2713427 | E37: =Assumptions!F372 -> 1842558 | F37: =Assumptions!G372 -> 1331168 | G37: =Assumptions!H372 -> 0 | H37: =Assumptions!I372 -> 0 | I37: =Assumptions!J372 -> 0 | ... K37: =Assumptions!L372 -> 0
A38: Provisions | B38: =Assumptions!C379 -> 0 | C38: =Assumptions!D379 -> 2991392 | D38: =Assumptions!E379 -> 1808405 | E38: =Assumptions!F379 -> 637807 | F38: =Assumptions!G379 -> 0 | G38: =Assumptions!H379 -> 1087520.8 | H38: =Assumptions!I379 -> 1305025 | I38: =Assumptions!J379 -> 967751.55 | ... K38: =Assumptions!L379 -> 831983.63
A39: Defered Tax Liability | B39: =Assumptions!C381 -> 0 | C39: =Assumptions!D381 -> 1199672 | D39: =Assumptions!E381 -> 2048549 | E39: =Assumptions!F381 -> 2155320 | F39: =Assumptions!G381 -> 3048430 | G39: =Assumptions!H381 -> 211186.6 | H39: =Assumptions!I381 -> 939339.4 | I39: =Assumptions!J381 -> 1667492.2 | ... K39: =Assumptions!L381 -> 3123797.8
B40: =SUM(B35:B39) -> 23932710 | C40: =SUM(C35:C39) -> 27595528 | D40: =SUM(D35:D39) -> 23798436 | E40: =SUM(E35:E39) -> 24149659 | F40: =SUM(F35:F39) -> 25502615 | G40: =SUM(G35:G39) -> 19845498 | H40: =SUM(H35:H39) -> 19460597 | I40: =SUM(I35:I39) -> 19602530 | ... K40: =SUM(K35:K39) -> 15524282
A41: Current Liabilitiies
A42: Trade and other payables | B42: =Assumptions!C415 -> 6539817 | C42: =Assumptions!D415 -> 9458730 | D42: =Assumptions!E415 -> 11533192 | E42: =Assumptions!F415 -> 14916145 | F42: =Assumptions!G415 -> 14390425 | G42: =Assumptions!H415 -> 15562145 | H42: =Assumptions!I415 -> 15072632 | I42: =Assumptions!J415 -> 16632040 | ... K42: =Assumptions!L415 -> 21109776
A43: Service benefit obligations | B43: =Assumptions!C418 -> 61049 | C43: =Assumptions!D418 -> 79539 | D43: =Assumptions!E418 -> 98298 | E43: =Assumptions!F418 -> 74278 | F43: =Assumptions!G418 -> 85166 | G43: =Assumptions!H418 -> 79666 | H43: =Assumptions!I418 -> 83389.4 | I43: =Assumptions!J418 -> 84159.48 | ... K43: =Assumptions!L418 -> 82742.531
...

Sheet Income Statement
A1: Engro Polymer & Chemicals ltd.
B4: Historical Data (000s) | G4: Forecasted Data (000s)
A5: Income Statement | B5: 2019 | C5: 2020 | D5: 2021 | E5: 2022 | F5: 2023 | G5: 2024 | H5: 2025 | I5: 2026 | J5: 2027 | K5: 2028
A7: Revenue from contracts with customers | B7: =Assumptions!C455 -> 37836632 | C7: =Assumptions!D455 -> 35331398 | D7: =Assumptions!E455 -> 70019594 | E7: =Assumptions!F455 -> 82059583 | F7: =Assumptions!G455 -> 81224448 | G7: =Assumptions!H455 -> 75781433 | H7: =Assumptions!I455 -> 73739481 | I7: =Assumptions!J455 -> 83720739 | ... K7: =Assumptions!L455 -> 1.0427884e+08
A8: Cost of sales | B8: =-'IS Assumptions'!B45 -> -29730593 | C8: =-'IS Assumptions'!C45 -> -24382129 | D8: =-'IS Assumptions'!D45 -> -45984328 | E8: =-'IS Assumptions'!E45 -> -58297565 | F8: =-'IS Assumptions'!F45 -> -60494597 | G8: =-'IS Assumptions'!G45 -> -55793551 | H8: =-'IS Assumptions'!H45 -> -54348193 | I8: =-'IS Assumptions'!I45 -> -61733036 | ... K8: =-'IS Assumptions'!K45 -> -74454001
A9: Gross profit | B9: =SUM(B7:B8) -> 8106039 | C9: =SUM(C7:C8) -> 10949269 | D9: =SUM(D7:D8) -> 24035266 | E9: =SUM(E7:E8) -> 23762018 | F9: =SUM(F7:F8) -> 20729851 | G9: =SUM(G7:G8) -> 19987882 | H9: =SUM(H7:H8) -> 19391288 | I9: =SUM(I7:I8) -> 21987703 | ... K9: =SUM(K7:K8) -> 29824840
A10: Distribution and marketing expenses | B10: =-'IS Assumptions'!B69 -> -391624 | C10: =-'IS Assumptions'!C69 -> -243269 | D10: =-'IS Assumptions'!D69 -> -376338 | E10: =-'IS Assumptions'!E69 -> -568871 | F10: =-'IS Assumptions'!F69 -> -811359 | G10: =-'IS Assumptions'!G69 -> -863988.05 | H10: =-'IS Assumptions'!H69 -> -463247.01 | I10: =-'IS Assumptions'!I69 -> -465741.38 | ... K10: =-'IS Assumptions'!K69 -> -1035891.8
A11: Administrative expenses | B11: =-'IS Assumptions'!B90 -> -565842 | C11: =-'IS Assumptions'!C90 -> -549854 | D11: =-'IS Assumptions'!D90 -> -682921 | E11: =-'IS Assumptions'!E90 -> -1329287 | F11: =-'IS Assumptions'!F90 -> -1617264 | G11: =-'IS Assumptions'!G90 -> -1026983.9 | H11: =-'IS Assumptions'!H90 -> -1112756.5 | I11: =-'IS Assumptions'!I90 -> -1136135.2 | ... K11: =-'IS Assumptions'!K90 -> -1634267.9
A12: Other expenses | B12: =-'IS Assumptions'!B100 -> -1214558 | C12: =-'IS Assumptions'!C100 -> -835788 | D12: =-'IS Assumptions'!D100 -> -2354195 | E12: =-'IS Assumptions'!E100 -> -3452360 | F12: =-'IS Assumptions'!F100 -> -1713102 | G12: =-'IS Assumptions'!G100 -> -2166320.2 | H12: =-'IS Assumptions'!H100 -> -2303034.2 | I12: =-'IS Assumptions'!I100 -> -2531886.7 | ... K12: =-'IS Assumptions'!K100 -> -2657319.9
A13: Other income | B13: ='IS Assumptions'!B123 -> 894262 | C13: ='IS Assumptions'!C123 -> 1086872 | D13: ='IS Assumptions'!D123 -> 1308468 | E13: ='IS Assumptions'!E123 -> 1442462 | F13: ='IS Assumptions'!F123 -> 1706456 | G13: ='IS Assumptions'!G123 -> 1295383.5 | H13: ='IS Assumptions'!H123 -> 1354869 | I13: ='IS Assumptions'!I123 -> 1401571.2 | ... K13: ='IS Assumptions'!K123 -> 1386904.3
A14: Operating profit | B14: =SUM(B9:B13) -> 6828277 | C14: =SUM(C9:C13) -> 10407230 | D14: =SUM(D9:D13) -> 21930280 | E14: =SUM(E9:E13) -> 19853962 | F14: =SUM(F9:F13) -> 18294582 | G14: =SUM(G9:G13) -> 17225973 | H14: =SUM(H9:H13) -> 16867119 | I14: =SUM(I9:I13) -> 19255510 | ... K14: =SUM(K9:K13) -> 25884264
A15: Finance costs | B15: =-'IS Assumptions'!B143 -> -1785583 | C15: =-'IS Assumptions'!C143 -> -2191097 | D15: =-'IS Assumptions'!D143 -> -1901939 | E15: =-'IS Assumptions'!E143 -> -3082932 | F15: =-'IS Assumptions'!F143 -> -4197208 | G15: =-'IS Assumptions'!G143 -> -1203698.8 | H15: =-'IS Assumptions'!H143 -> -987200.71 | I15: =-'IS Assumptions'!I143 -> -1213952.1 | ... K15: =-'IS Assumptions'!K143 -> -1157780.2
A16: Profit before taxation | B16: =SUM(B14:B15) -> 5042694 | C16: =SUM(C14:C15) -> 8216133 | D16: =SUM(D14:D15) -> 20028341 | E16: =SUM(E14:E15) -> 16771030 | F16: =SUM(F14:F15) -> 14097374 | G16: =SUM(G14:G15) -> 16022274 | H16: =SUM(H14:H15) -> 15879918 | I16: =SUM(I14:I15) -> 18041558 | ... K16: =SUM(K14:K15) -> 24726484
A17: Taxation | B17: =-'IS Assumptions'!B154 -> -1339192 | C17: =-'IS Assumptions'!C154 -> -2503888 | D17: =-'IS Assumptions'!D154 -> -4925730 | E17: =-'IS Assumptions'!E154 -> -5004035 | F17: =-'IS Assumptions'!F154 -> -4866714 | G17: =-'IS Assumptions'!G154 -> -3746417.2 | H17: =-'IS Assumptions'!H154 -> -4209356.8 | I17: =-'IS Assumptions'!I154 -> -4550450.6 | ... K17: =-'IS Assumptions'!K154 -> -4369666.7
A18: Profit for the year | B18: =SUM(B16:B17) -> 3703502 | C18: =SUM(C16:C17) -> 5712245 | D18: =SUM(D16:D17) -> 15102611 | E18: =SUM(E16:E17) -> 11766995 | F18: =SUM(F16:F17) -> 9230660 | G18: =SUM(G16:G17) -> 12275857 | H18: =SUM(H16:H17) -> 11670561 | I18: =SUM(I16:I17) -> 13491108 | ... K18: =SUM(K16:K17) -> 20356817
A20: Dividends paid | B20: =Assumptions!C611 -> -839879 | C20: =Assumptions!D611 -> -184969 | D20: =Assumptions!E611 -> -10213054 | E20: =Assumptions!F611 -> -14390460 | F20: =Assumptions!G611 -> -7930739 | G20: =Assumptions!H611 -> -3068964.3 | H20: =Assumptions!I611 -> -2917640.3 | I20: =Assumptions!J611 -> -3372776.9 | ... K20: =Assumptions!L611 -> -5089204.3
A21: Profit Retained | B21: =B18+B20 -> 2863623 | C21: =C18+C20 -> 5527276 | D21: =D18+D20 -> 4889557 | E21: =E18+E20 -> -2623465 | F21: =F18+F20 -> 1299921 | G21: =G18+G20 -> 9206892.9 | H21: =H18+H20 -> 8752921 | I21: =I18+I20 -> 10118331 | ... K21: =K18+K20 -> 15267613
A23: Earnings per share - basic | B23: =B18/'IS Assumptions'!B156 -> 4.0746048 | C23: =C18/'IS Assumptions'!C156 -> 6.2846303 | D23: =D18/'IS Assumptions'!D156 -> 16.615941 | E23: =E18/'IS Assumptions'!E156 -> 12.946086 | F23: =F18/'IS Assumptions'!F156 -> 10.155602 | G23: =G18/'IS Assumptions'!G156 -> 13.505937 | H23: =H18/'IS Assumptions'!H156 -> 12.839989 | I23: =I18/'IS Assumptions'!I156 -> 14.84296 | ... K23: =K18/'IS Assumptions'!K156 -> 22.396636
A24: Earnings per share - diluted | B24: =B18/'IS Assumptions'!B157 -> 4.0746048 | C24: =C18/'IS Assumptions'!C157 -> 6.2118045 | D24: =D18/'IS Assumptions'!D157 -> 12.492616 | E24: =E18/'IS Assumptions'!E157 -> 9.7334528 | F24: =F18/'IS Assumptions'!F157 -> 7.6354408 | G24: =G18/'IS Assumptions'!G157 -> 10.154375 | H24: =H18/'IS Assumptions'!H157 -> 9.6536846 | I24: =I18/'IS Assumptions'!I157 -> 11.159609 | ... K24: =K18/'IS Assumptions'!K157 -> 16.838804
A26: =A18 -> Profit for the year | B26: =B18 -> 3703502 | C26: =C18 -> 5712245 | D26: =D18 -> 15102611 | E26: =E18 -> 11766995 | F26: =F18 -> 9230660 | G26: =G18 -> 12275857 | H26: =H18 -> 11670561 | ... K26: =K18 -> 20356817
A27: =A21 -> Profit Retained | B27: =B21 -> 2863623 | C27: =C21 -> 5527276 | D27: =D21 -> 4889557 | E27: =E21 -> -2623465 | F27: =F21 -> 1299921 | G27: =G21 -> 9206892.9 | H27: =H21 -> 8752921 | ... K27: =K21 -> 15267613

Sheet CashFlow
A1: Engro Polymer & Chemicals ltd.
B4: Historical Data (000s) | G4: Forecasted Data (000s)
A5: Cashflow statement | B5: 2019 | C5: 2020 | D5: 2021 | E5: 2022 | F5: 2023 | G5: 2024 | H5: 2025 | I5: 2026 | J5: 2027 | K5: 2028
A7: CASH FLOWS FROM OPERATING ACTIVITIES
A8: Cash generated from operations | B8: 9040561 | C8: 12575886 | D8: 17606714 | E8: 24654512 | F8: 13282584 | G8: =Assumptions!H656 -> 32077091 | H8: =Assumptions!I656 -> 20159150 | I8: =Assumptions!J656 -> 21722683 | J8: =Assumptions!K656 -> 25221885 | K8: =Assumptions!L656 -> 29751756
A9: Long-term loans and advances, net | B9: 12387 | C9: 42792 | D9: 28612 | E9: 674 | F9: -21837 | G9: =Assumptions!H583 -> 21816.732 | H9: =Assumptions!I583 -> 8520.242 | I9: =Assumptions!J583 -> 6262.5515 | J9: =Assumptions!K583 -> 8768.3988 | K9: =Assumptions!L583 -> 14463.749
A10: Retirement benefits paid | B10: -45428 | C10: -34528 | D10: -42226 | E10: -92789 | F10: -67404 | G10: =Assumptions!H584 -> -76219.632 | H10: =Assumptions!I584 -> -82661.02 | I10: =Assumptions!J584 -> -89102.408 | J10: =Assumptions!K584 -> -95543.796 | K10: =Assumptions!L584 -> -101985.18
A11: Income tax paid | B11: -1278914 | C11: -1260635 | D11: -2903171 | E11: -3009757 | F11: -6638753 | G11: =Assumptions!H585 -> -3768898.3 | H11: =Assumptions!I585 -> -3735412.1 | I11: =Assumptions!J585 -> -4243891.8 | J11: =Assumptions!K585 -> -4709802.6 | K11: =Assumptions!L585 -> -5816378
A12: Net cash generated from operating activities | B12: =SUM(B8:B11) -> 7728606 | C12: =SUM(C8:C11) -> 11323515 | D12: =SUM(D8:D11) -> 14689929 | E12: =SUM(E8:E11) -> 21552640 | F12: =SUM(F8:F11) -> 6554590 | G12: =SUM(G8:G11) -> 28253790 | H12: =SUM(H8:H11) -> 16349597 | I12: =SUM(I8:I11) -> 17395952 | ... K12: =SUM(K8:K11) -> 23847857
A14: CASH FLOWS FROM INVESTING ACTIVITIES
A15: Purchases of property, plant, and equipment and intangible assets | B15: -12744841 | C15: -6091440 | D15: -2869090 | E15: -6765766 | F15: -6803718 | G15: =Assumptions!H589 -> -8619456.1 | H15: =Assumptions!I589 -> -7933316.1 | I15: =Assumptions!J589 -> -9057192.5 | J15: =Assumptions!K589 -> -10448090 | K15: =Assumptions!L589 -> -7396149.5
A16: Proceeds from disposal of property, plant, and equipment | B16: 2809 | C16: -167922 | D16: -248406 | E16: 29385 | F16: 44320 | G16: =Assumptions!H590 -> -37742.915 | H16: =Assumptions!I590 -> -30490.646 | I16: =Assumptions!J590 -> -25684.279 | J16: =Assumptions!K590 -> -191481.37 | K16: =Assumptions!L590 -> -28531.751
A17: Investments in subsidiary companies | B17: -1575000 | C17: - | D17: 2601 | E17: -1419000 | F17: -2953000 | G17: =Assumptions!H591 -> -2472734 | H17: =Assumptions!I591 -> -2472734 | I17: =Assumptions!J591 -> -2472734 | J17: =Assumptions!K591 -> -2472734 | K17: =Assumptions!L591 -> -2472734
A18: Investment made in Term deposit receipts | B18: -5421150 | C18: -6000 | G18: =Assumptions!H592 -> 0 | H18: =Assumptions!I592 -> 0 | I18: =Assumptions!J592 -> 0 | J18: =Assumptions!K592 -> 0 | K18: =Assumptions!L592 -> 0
A19: Disbursement of subordinated loan to subsidiary companies | C19: - | D19: -840000 | E19: - | F19: -5050800 | G19: =Assumptions!H593 -> -1178160 | H19: =Assumptions!I593 -> -1413792 | I19: =Assumptions!J593 -> -1696550.4 | J19: =Assumptions!K593 -> -2035860.5 | K19: =Assumptions!L593 -> -2443032.6
A20: Repayment of subordinated loan from subsidiary companies | D20: - | E20: - | F20: 3630300 | G20: =Assumptions!H594 -> 726060 | H20: =Assumptions!I594 -> 871272 | I20: =Assumptions!J594 -> 1045526.4 | J20: =Assumptions!K594 -> 1254631.7 | K20: =Assumptions!L594 -> 1505558
A21: Purchase of short-term investments | D21: -10972500 | E21: -340467497 | F21: -40642094 | G21: =Assumptions!H595 -> -60512157 | H21: =Assumptions!I595 -> -51951689 | I21: =Assumptions!J595 -> -41534656 | J21: =Assumptions!K595 -> -51332834 | K21: =Assumptions!L595 -> -48273060
A22: Proceeds on sale/maturity of short-term investments | C22: - | D22: 3934667 | E22: 339467894 | F22: 53928691 | G22: =Assumptions!H596 -> 61322288 | H22: =Assumptions!I596 -> 52647214 | I22: =Assumptions!J596 -> 42090718 | J22: =Assumptions!K596 -> 52020073 | K22: =Assumptions!L596 -> 48919335
A23: Income on short-term investments, subordinated loan, intercompany balances, and deposits | B23: 816760 | C23: 979007 | D23: 1276182 | E23: 1272366 | F23: 852743 | G23: =Assumptions!H597 -> 810774.81 | H23: =Assumptions!I597 -> 1004990.4 | I23: =Assumptions!J597 -> 1216416.7 | J23: =Assumptions!K597 -> 1413954.5 | K23: =Assumptions!L597 -> 1519424.1
A24: Net cash generated from / (utilised in) investing activities | B24: =SUM(B15:B23) -> -18921422 | C24: =SUM(C15:C23) -> -5286355 | D24: =SUM(D15:D23) -> -9716546 | E24: =SUM(E15:E23) -> -7882618 | F24: =SUM(F15:F23) -> 3006442 | G24: =Assumptions!H598 -> -9961126.7 | H24: =Assumptions!I598 -> -9278545.6 | I24: =Assumptions!J598 -> -10434156 | J24: =Assumptions!K598 -> -11792340 | K24: =Assumptions!L598 -> -8669190.2
G25: =Assumptions!H599 -> 0 | H25: =Assumptions!I599 -> 0 | I25: =Assumptions!J599 -> 0 | J25: =Assumptions!K599 -> 0 | K25: =Assumptions!L599 -> 0
A26: CASH FLOWS FROM FINANCING ACTIVITIES | G26: =Assumptions!H600 -> 0 | H26: =Assumptions!I600 -> 0 | I26: =Assumptions!J600 -> 0 | J26: =Assumptions!K600 -> 0 | K26: =Assumptions!L600 -> 0
A27: Proceeds from long-term borrowings - net of transaction costs | B27: 19366880 | C27: 2019133 | D27: 928549 | E27: 14948531 | F27: 4293727 | G27: =Assumptions!H601 -> 2299068.1 | H27: =Assumptions!I601 -> 1545165.2 | I27: =Assumptions!J601 -> 2489500.8 | J27: =Assumptions!K601 -> 1748552.2 | K27: =Assumptions!L601 -> 2448175.9
A28: Repayments of long-term borrowings | B28: -7500000 | D28: -1926515 | E28: -12876271 | F28: -5128274 | G28: =Assumptions!H602 -> -1517581.8 | H28: =Assumptions!I602 -> -1019941.4 | I28: =Assumptions!J602 -> -1643283.7 | J28: =Assumptions!K602 -> -1154194.2 | K28: =Assumptions!L602 -> -1616005.7
A29: Proceeds from short-term borrowings | C29: -190586 | D29: 474360 | E29: - | F29: 324360 | G29: =Assumptions!H603 -> 10167.604 | H29: =Assumptions!I603 -> 23117.226 | I29: =Assumptions!J603 -> 121626.8 | J29: =Assumptions!K603 -> 220136.37 | K29: =Assumptions!L603 -> 318645.95
A30: Repayment of short-term borrowings | C30: 3000000 | E30: - | F30: -474360 | G30: =Assumptions!H604 -> 42227.053 | H30: =Assumptions!I604 -> 96008.103 | I30: =Assumptions!J604 -> 505128 | J30: =Assumptions!K604 -> 914247.9 | K30: =Assumptions!L604 -> 1323367.8
A31: Proceeds of subordinated loan from the holding company | C31: - | E31: - | F31: 1700000 | G31: =Assumptions!H605 -> 340000 | H31: =Assumptions!I605 -> 340000 | I31: =Assumptions!J605 -> 340000 | J31: =Assumptions!K605 -> 340000 | K31: =Assumptions!L605 -> 340000
A32: Repayment of subordinated loan to the holding company | E32: - | F32: -1700000 | G32: =Assumptions!H606 -> -340000 | H32: =Assumptions!I606 -> -340000 | I32: =Assumptions!J606 -> -340000 | J32: =Assumptions!K606 -> -340000 | K32: =Assumptions!L606 -> -340000
A33: Proceeds of subordinated loan from subsidiary company | E33: - | F33: 400000 | G33: =Assumptions!H607 -> 166390.85 | H33: =Assumptions!I607 -> 166390.85 | I33: =Assumptions!J607 -> 166390.85 | J33: =Assumptions!K607 -> 166390.85 | K33: =Assumptions!L607 -> 166390.85
A34: Repayment of subordinated loan to subsidiary company | E34: - | F34: -400000 | G34: =Assumptions!H608 -> -166390.85 | H34: =Assumptions!I608 -> -166390.85 | I34: =Assumptions!J608 -> -166390.85 | J34: =Assumptions!K608 -> -166390.85 | K34: =Assumptions!L608 -> -166390.85
A35: Finance costs paid | B35: -998523 | C35: -1891139 | D35: -1353532 | E35: -2311808 | F35: -4531992 | G35: =Assumptions!H609 -> -1102612.3 | H35: =Assumptions!I609 -> -904295.67 | I35: =Assumptions!J609 -> -1112004.5 | J35: =Assumptions!K609 -> -963752.84 | K35: =Assumptions!L609 -> -1060549.9
A36: Lease rentals paid | B36: -1241425 | C36: -1337444 | D36: -1372441 | E36: -1720502 | F36: -2372703 | G36: =Assumptions!H610 -> -3492221.2 | H36: =Assumptions!I610 -> -3152108.7 | I36: =Assumptions!J610 -> 0 | J36: =Assumptions!K610 -> 0 | K36: =Assumptions!L610 -> 0
A37: Dividend paid | B37: -839879 | C37: -184969 | D37: -10213054 | E37: -14390460 | F37: -7930739 | G37: =Assumptions!H611 -> -3068964.3 | H37: =Assumptions!I611 -> -2917640.3 | I37: =Assumptions!J611 -> -3372776.9 | J37: =Assumptions!K611 -> -3886708.8 | K37: =Assumptions!L611 -> -5089204.3
A38: Net cash utilised in financing activities | B38: =SUM(B27:B37) -> 8787053 | C38: =SUM(C27:C37) -> 1414995 | D38: =SUM(D27:D37) -> -13462633 | E38: =SUM(E27:E37) -> -16350510 | F38: =SUM(F27:F37) -> -15819981 | G38: =Assumptions!H612 -> -6829916.9 | H38: =Assumptions!I612 -> -6329695.5 | I38: =Assumptions!J612 -> -3011809.5 | J38: =Assumptions!K612 -> -3121719.4 | K38: =Assumptions!L612 -> -3675570.3
G39: =Assumptions!H613 -> 0 | H39: =Assumptions!I613 -> 0 | I39: =Assumptions!J613 -> 0 | J39: =Assumptions!K613 -> 0 | K39: =Assumptions!L613 -> 0
G40: =Assumptions!H614 -> 0 | H40: =Assumptions!I614 -> 0 | I40: =Assumptions!J614 -> 0 | J40: =Assumptions!K614 -> 0 | K40: =Assumptions!L614 -> 0
A41: Net decrease in cash and cash equivalents | B41: =B38+B24+B12 -> -2405763 | C41: =C38+C24+C12 -> 7452155 | D41: =D38+D24+D12 -> -8489250 | E41: =E38+E24+E12 -> -2680488 | F41: =F38+F24+F12 -> -6258949 | G41: =Assumptions!H615 -> -16791044 | H41: =Assumptions!I615 -> -15608241 | I41: =Assumptions!J615 -> -13445965 | J41: =Assumptions!K615 -> -14914060 | K41: =Assumptions!L615 -> -12344761
A42: Net foreign exchange differences | C42: 6834 | D42: 39600 | E42: 28419 | F42: 434307 | G42: =Assumptions!H616 -> 753533.74 | H42: =Assumptions!I616 -> 896851.64 | I42: =Assumptions!J616 -> 1039994.6 | J42: =Assumptions!K616 -> 1182977.4 | K42: =Assumptions!L616 -> 1325813.1
A43: Cash and cash equivalents at beginning of the year | B43: 9062267 | C43: 6656504 | D43: 14115493 | E43: 5665843 | F43: 3013774 | G43: =Assumptions!H617 -> -2810868 | H43: =Assumptions!I617 -> -18848378 | I43: =Assumptions!J617 -> -33559767 | J43: =Assumptions!K617 -> -45965738 | K43: =Assumptions!L617 -> -59696820
A44: Cash and cash equivalents at end of the year | B44: =SUM(B41:B43) -> 6656504 | C44: =SUM(C41:C43) -> 14115493 | D44: =SUM(D41:D43) -> 5665843 | E44: =SUM(E41:E43) -> 3013774 | F44: =SUM(F41:F43) -> -2810868 | G44: =SUM(G41:G43) -> -18848378 | H44: =SUM(H41:H43) -> -33559767 | I44: =SUM(I41:I43) -> -45965738 | ... K44: =SUM(K41:K43) -> -70715768

Sheet Regression
B4: GROSS SALES REGRESSION
B5: Year | C5: Gross Sales | D5: CPI Inflation | E5: GDP Growth rates | F5: modernization% | J5: SUMMARY OUTPUT
B6: 2019 | C6: 44223191 | D6: 0.094 | E6: 0.031 | F6: 0.03
B7: 2020 | C7: 42002709 | D7: 0.095 | E7: -0.009 | F7: 0.029 | J7: Regression Statistics
B8: 2021 | C8: 77442765 | D8: 0.095 | E8: 0.058 | F8: 0.0279 | J8: Multiple R | K8: 0.99999168
B9: 2022 | C9: 92990439 | D9: 0.199 | E9: 0.062 | F9: 0.028 | J9: R Square | K9: 0.99998336
B10: 2023 | C10: 89862918 | D10: 0.308 | E10: -0.002 | F10: 0.0277 | J10: Adjusted R Square | K10: 0.99993344
B11: 2024 | C11: =$K$21+$K$22*D11+E11*$K$23+F11*$K$24 -> 82029148 | D11: 0.173 | E11: 0.0252 | F11: 0.0275 | J11: Standard Error | K11: 200854.45
B12: 2025 | C12: =$K$21+$K$22*D12+E12*$K$23+F12*$K$24 -> 79460814 | D12: 0.1 | E12: 0.032 | F12: 0.027 | J12: Observations | K12: 5
B13: 2026 | C13: =$K$21+$K$22*D13+E13*$K$23+F13*$K$24 -> 90649902 | D13: 0.08 | E13: 0.04 | F13: 0.026
B14: 2027 | C14: =$K$21+$K$22*D14+E14*$K$23+F14*$K$24 -> 1.0052198e+08 | D14: 0.07 | E14: 0.04 | F14: 0.025 | J14: ANOVA
B15: 2028 | C15: =$K$21+$K$22*D15+E15*$K$23+F15*$K$24 -> 1.1145006e+08 | D15: 0.0649 | E15: 0.041 | F15: 0.024 | K15: df | L15: SS | M15: MS | N15: F | O15: Significance F
J16: Regression | K16: 3 | L16: 2.4243231e+15 | M16: 8.0810771e+14 | N16: 20031.17 | O16: 0.0051938753
J17: Residual | K17: 1 | L17: 4.0342512e+10 | M17: 4.0342512e+10
J18: Total | K18: 4 | L18: 2.4243635e+15
K20: Coefficients | L20: Standard Error | M20: t Stat | N20: P-value | O20: Lower 95% | P20: Upper 95% | Q20: Lower 95.0% | R20: Upper 95.0%
J21: Intercept | K21: 3.5958094e+08 | L21: 4451573.7 | M21: 80.77614 | N21: 0.0078808823 | O21: 3.0301833e+08 | P21: 4.1614354e+08 | Q21: 3.0301833e+08 | R21: 4.1614354e+08
J22: CPI Inflation | K22: 1.4493831e+08 | L22: 1520777.9 | M22: 95.305379 | N22: 0.0066795433 | O22: 1.25615e+08 | P22: 1.6426163e+08 | Q22: 1.25615e+08 | R22: 1.6426163e+08
J23: GDP Growth rates | K23: 3.4579876e+08 | L23: 3500078.6 | M23: 98.797428 | N23: 0.0064434677 | O23: 3.0132605e+08 | P23: 3.9027148e+08 | Q23: 3.0132605e+08 | R23: 3.9027148e+08
J24: modernization% | K24: -1.1321464e+10 | L24: 1.4843353e+08 | M24: -76.272952 | N24: 0.0083461212 | O24: -1.320749e+10 | P24: -9.4354367e+09 | Q24: -1.320749e+10 | R24: -9.4354367e+09
B26: EXPORT SALES REGRESSION
B27: Year | C27: Export sales | D27: Pak rupee per Usdollar | E27: Real GDP growth (Annual percent change) | J27: SUMMARY OUTPUT
B28: 2019 | C28: 469164 | D28: 154.92001 | E28: 0.031
B29: 2020 | C29: 158059 | D29: 160.0795 | E29: -0.009 | J29: Regression Statistics
B30: 2021 | C30: 4805957 | D30: 177.1764 | E30: 0.058 | J30: Multiple R | K30: 0.93022134
B31: 2022 | C31: 4479059 | D31: 224.7624 | E31: 0.062 | J31: R Square | K31: 0.86531173
B32: 2023 | C32: 7294749 | D32: 283.2961 | E32: -0.002 | J32: Adjusted R Square | K32: 0.73062346
B33: 2024 | C33: =$K$43+$K$44*D33+E33*$K$45 -> 7317665.5 | D33: 276 | E33: 0.0252 | J33: Standard Error | K33: 1587065.2
B34: 2025 | C34: =$K$43+$K$44*D34+E34*$K$45 -> 7410021.6 | D34: 274 | E34: 0.032 | J34: Observations | K34: 5
B35: 2026 | C35: =$K$43+$K$44*D35+E35*$K$45 -> 8058070.3 | D35: 282 | E35: 0.04
B36: 2027 | C36: =$K$43+$K$44*D36+E36*$K$45 -> 10037893 | D36: 320 | E36: 0.04 | J36: ANOVA
B37: 2028 | C37: =$K$43+$K$44*D37+E37*$K$45 -> 11265113 | D37: 343 | E37: 0.041 | K37: df | L37: SS | M37: MS | N37: F | O37: Significance F
J38: Regression | K38: 2 | L38: 3.2364013e+13 | M38: 1.6182007e+13 | N38: 6.4245516 | O38: 0.13468827
J39: Residual | K39: 2 | L39: 5.0375521e+12 | M39: 2.518776e+12
J40: Total | K40: 4 | L40: 3.7401565e+13 | T40: SUMMARY OUTPUT
B41: Raw Materials Regression
B42: Year | C42: Raw Material | D42: Inflation | E42: Export sales | F42: Gross Sales | K42: Coefficients | L42: Standard Error | M42: t Stat | N42: P-value | O42: Lower 95% | P42: Upper 95% | Q42: Lower 95.0% | R42: Upper 95.0% | T42: Regression Statistics
B43: 2019 | C43: 17274480 | D43: =D6 -> 0.094 | E43: =C28 -> 469164 | F43: =C6 -> 44223191 | J43: Intercept | K43: -7790519.2 | L43: 3213427.2 | M43: -2.4243646 | N43: 0.13622123 | O43: -21616781 | P43: 6035742.1 | Q43: -21616781 | R43: 6035742.1 | T43: Multiple R | U43: 0.99145481
B44: 2020 | C44: 11425736 | D44: =D7 -> 0.095 | E44: =C29 -> 158059 | F44: =C7 -> 42002709 | J44: X Variable 1 | K44: 52100.603 | L44: 14820.41 | M44: 3.5154629 | N44: 0.0722557 | O44: -11666.476 | P44: 115867.68 | Q44: -11666.476 | R44: 115867.68 | T44: R Square | U44: 0.98298263
B45: 2021 | C45: 31987105 | D45: =D8 -> 0.095 | E45: =C30 -> 4805957 | F45: =C8 -> 77442765 | J45: X Variable 2 | K45: 28905489 | L45: 24348646 | M45: 1.1871497 | N45: 0.35705869 | O45: -75858279 | P45: 1.3366926e+08 | Q45: -75858279 | R45: 1.3366926e+08 | T45: Adjusted R Square | U45: 0.93193054
...

Sheet Loan Schedule
A2: In 2018, the Company had entered into a financing agreement with IFC for a total of USD 35,000, the draw down of which was made in December 2019. This is secured by way of hypothecation charge of present and future fixed assets of the Company (excluding land and building) to the extent of USD 43,750 which shall rank pari passu with the charges created in favour of the existing creditors.
A5: 18.1
A6: Principal Outstanding | B6: =35000*154.84 -> 5419400
A7: Spread (annual) | B7: 0.0325 | D7: Date | E7: 44211 | F7: =EDATE(E7,6) -> 44392 | G7: =EDATE(F7,6) -> 44576 | H7: =EDATE(G7,6) -> 44757 | I7: =EDATE(H7,6) -> 44941 | J7: =EDATE(I7,6) -> 45122 | K7: =EDATE(J7,6) -> 45306 | L7: =EDATE(K7,6) -> 45488 | M7: =EDATE(L7,6) -> 45672 | ... O7: =EDATE(N7,6) -> 46037
A8: Frequency | B8: 2 | D8: Spread | F8: =$B$7 -> 0.0325 | G8: =$B$7 -> 0.0325 | H8: =$B$7 -> 0.0325 | I8: =$B$7 -> 0.0325 | J8: =$B$7 -> 0.0325 | K8: =$B$7 -> 0.0325 | L8: =$B$7 -> 0.0325 | M8: =$B$7 -> 0.0325 | ... O8: =$B$7 -> 0.0325
A9: Years | B9: 3 | D9: LIBOR (6 M) | F9: 0.0015325 | G9: 0.0041814 | H9: 0.0331129 | I9: 0.0511543 | J9: 0.0582461 | K9: 0.0558173 | L9: 0.0557884
A10: Periods | B10: 6 | D10: Period | F10: 1 | G10: 2 | H10: 3 | I10: 4 | J10: 5 | K10: 6 | L10: 7 | M10: 8 | N10: 9 | O10: 10
D11: Rate | F11: =(F9+F8)/2 -> 0.01701625 | G11: =(G9+G8)/2 -> 0.0183407 | H11: =(H9+H8)/2 -> 0.03280645 | I11: =(I9+I8)/2 -> 0.04182715 | J11: =(J9+J8)/2 -> 0.04537305 | K11: =(K9+K8)/2 -> 0.04415865 | L11: =(L9+L8)/2 -> 0.0441442 | M11: =(M9+M8)/2 -> 0.01625 | ... O11: =(O9+O8)/2 -> 0.01625
D12: Opening Balance | F12: =B6 -> 5419400 | G12: =F16 -> 4516166.7 | H12: =G16 -> 3612933.3 | I12: =H16 -> 2709700 | J12: =I16 -> 1806466.7 | K12: =J16 -> 903233.33 | L12: =K16 -> 0 | M12: =L16 -> 0 | N12: =M16 -> 0 | O12: =N16 -> 0
D13: Interest | F13: =IF(F10<=$B$10,F12*F11,0) -> 92217.865 | G13: =IF(G10<=$B$10,G12*G11,0) -> 82829.658 | H13: =IF(H10<=$B$10,H12*H11,0) -> 118527.52 | I13: =IF(I10<=$B$10,I12*I11,0) -> 113339.03 | J13: =IF(J10<=$B$10,J12*J11,0) -> 81964.902 | K13: =IF(K10<=$B$10,K12*K11,0) -> 39885.565 | L13: =IF(L10<=$B$10,L12*L11,0) -> 0 | M13: =IF(M10<=$B$10,M12*M11,0) -> 0 | ... O13: =IF(O10<=$B$10,O12*O11,0) -> 0
D14: Principal PMT | F14: =IF(F10<=$B$10,$B$6/$B$10,0) -> 903233.33 | G14: =IF(G10<=$B$10,$B$6/$B$10,0) -> 903233.33 | H14: =IF(H10<=$B$10,$B$6/$B$10,0) -> 903233.33 | I14: =IF(I10<=$B$10,$B$6/$B$10,0) -> 903233.33 | J14: =IF(J10<=$B$10,$B$6/$B$10,0) -> 903233.33 | K14: =IF(K10<=$B$10,$B$6/$B$10,0) -> 903233.33 | L14: =IF(L10<=$B$10,$B$6/$B$10,0) -> 0 | M14: =IF(M10<=$B$10,$B$6/$B$10,0) -> 0 | ... O14: =IF(O10<=$B$10,$B$6/$B$10,0) -> 0
D15: Total PMT | F15: =F14+F13 -> 995451.2 | G15: =G14+G13 -> 986062.99 | H15: =H14+H13 -> 1021760.9 | I15: =I14+I13 -> 1016572.4 | J15: =J14+J13 -> 985198.24 | K15: =K14+K13 -> 943118.9 | L15: =L14+L13 -> 0 | M15: =M14+M13 -> 0 | ... O15: =O14+O13 -> 0
D16: Closing balance | F16: =F12-F14 -> 4516166.7 | G16: =G12-G14 -> 3612933.3 | H16: =H12-H14 -> 2709700 | I16: =I12-I14 -> 1806466.7 | J16: =J12-J14 -> 903233.33 | K16: =K12-K14 -> 0 | L16: =L12-L14 -> 0 | M16: =M12-M14 -> 0 | ... O16: =O12-O14 -> 0
F18: 2021 | G18: 2022 | H18: 2023 | I18: 2024 | J18: 2025
D19: Opening Balance | F19: =F12 -> 5419400 | G19: =F23 -> 4516166.7 | H19: =G23 -> 2709700 | I19: =H23 -> 903233.33 | J19: =I23 -> 0
D20: Interest | F20: =E13+F13 -> 92217.865 | G20: =G13+H13 -> 201357.17 | H20: =J13+I13 -> 195303.93 | I20: =L13+K13 -> 39885.565 | J20: =M13+N13 -> 0
D21: Principal PMT | F21: =E14+F14 -> 903233.33 | G21: =G14+H14 -> 1806466.7 | H21: =J14+I14 -> 1806466.7 | I21: =L14+K14 -> 903233.33 | J21: =M14+N14 -> 0
D22: Total PMT | F22: =E15+F15 -> 995451.2 | G22: =G15+H15 -> 2007823.8 | H22: =J15+I15 -> 2001770.6 | I22: =L15+K15 -> 943118.9 | J22: =M15+N15 -> 0
D23: Closing Balance | F23: =F19-F21 -> 4516166.7 | G23: =G19-G21 -> 2709700 | H23: =H19-H21 -> 903233.33 | I23: =I19-I21 -> 0 | J23: =J19-J21 -> 0
A25: In 2019, the Company entered into a musharaka agreement with Dubai Islamic Bank Pakistan Limited (DIBPL). The borrowing is secured by way of hypothecation charge of present and future fixed assets of the Company (except land and building) to the extent of Rs. 1,199,450, ranking subordinate and subservient to the charges created in favour of the existing creditors, and a lien and a right of set-off over the Term Deposit Receipts maintained with DIBPL (note 8).
A29: 18.2 | D29: Spread | F29: =B31 -> 0 | G29: =F29 -> 0 | H29: =G29 -> 0 | I29: =H29 -> 0 | J29: =I29 -> 0 | K29: =J29 -> 0 | L29: =K29 -> 0 | M29: =L29 -> 0 | N29: =M29 -> 0 | O29: =N29 -> 0
A30: Principal Outstanding | B30: 5421500 | D30: KIBOR (6 M) | F30: 0.0736 | G30: 0.112 | H30: 0.1554 | I30: 0.1686 | J30: 0.2265 | K30: 0.2058 | L30: 0.1967
A31: Spread (annual) | B31: 0 | D31: Period | F31: 1 | G31: 2 | H31: 3 | I31: 4 | J31: 5 | K31: 6 | L31: 7 | M31: 8 | N31: 9 | O31: 10
A32: Frequency | B32: 2 | D32: Date | E32: 44211 | F32: =EDATE(E32,6) -> 44392 | G32: =EDATE(F32,6) -> 44576 | H32: =EDATE(G32,6) -> 44757 | I32: =EDATE(H32,6) -> 44941 | J32: =EDATE(I32,6) -> 45122 | K32: =EDATE(J32,6) -> 45306 | L32: =EDATE(K32,6) -> 45488 | M32: =EDATE(L32,6) -> 45672 | ... O32: =EDATE(N32,6) -> 46037
A33: Years | B33: 3 | D33: Rate | F33: =(F29+F30)/2 -> 0.0368 | G33: =(G29+G30)/2 -> 0.056 | H33: =(H29+H30)/2 -> 0.0777 | I33: =(I29+I30)/2 -> 0.0843 | J33: =(J29+J30)/2 -> 0.11325 | K33: =(K29+K30)/2 -> 0.1029 | L33: =(L29+L30)/2 -> 0.09835 | M33: =(M29+M30)/2 -> 0 | ... O33: =(O29+O30)/2 -> 0
A34: Periods | B34: =B32*B33 -> 6 | D34: Opening Balance | F34: =B30 -> 5421500 | G34: =F38 -> 4517916.7 | H34: =G38 -> 3614333.3 | I34: =H38 -> 2710750 | J34: =I38 -> 1807166.7 | K34: =J38 -> 903583.33 | L34: =K38 -> 0 | M34: =L38 -> 0 | N34: =M38 -> 0 | O34: =N38 -> 0
D35: Interest | F35: =IF(F31<=$B$34,F34*F33,0) -> 199511.2 | G35: =IF(G31<=$B$10,G34*G33,0) -> 253003.33 | H35: =IF(H31<=$B$10,H34*H33,0) -> 280833.7 | I35: =IF(I31<=$B$10,I34*I33,0) -> 228516.23 | J35: =IF(J31<=$B$10,J34*J33,0) -> 204661.62 | K35: =IF(K31<=$B$10,K34*K33,0) -> 92978.725 | L35: =IF(L31<=$B$10,L34*L33,0) -> 0 | M35: =IF(M31<=$B$10,M34*M33,0) -> 0 | N35: =IF(N31<=$B$10,N34*N33,0) -> 0 | O35: =IF(O31<=$B$10,O34*O33,0) -> 0
D36: Principal PMT | F36: =IF(F31<=$B$34,$B$30/$B$34,0) -> 903583.33 | G36: =IF(G31<=$B$34,$B$30/$B$34,0) -> 903583.33 | H36: =IF(H31<=$B$34,$B$30/$B$34,0) -> 903583.33 | I36: =IF(I31<=$B$34,$B$30/$B$34,0) -> 903583.33 | J36: =IF(J31<=$B$34,$B$30/$B$34,0) -> 903583.33 | K36: =IF(K31<=$B$34,$B$30/$B$34,0) -> 903583.33 | L36: =IF(L31<=$B$34,$B$30/$B$34,0) -> 0 | M36: =IF(M31<=$B$34,$B$30/$B$34,0) -> 0 | ... O36: =IF(O31<=$B$34,$B$30/$B$34,0) -> 0
D37: Total PMT | F37: =SUM(F35+F36) -> 1103094.5 | G37: =SUM(G35+G36) -> 1156586.7 | H37: =SUM(H35+H36) -> 1184417 | I37: =SUM(I35+I36) -> 1132099.6 | J37: =SUM(J35+J36) -> 1108245 | K37: =SUM(K35+K36) -> 996562.06 | L37: =SUM(L35+L36) -> 0 | M37: =SUM(M35+M36) -> 0 | ... O37: =SUM(O35+O36) -> 0
D38: Closing balance | F38: =F34-F36 -> 4517916.7 | G38: =G34-G36 -> 3614333.3 | H38: =H34-H36 -> 2710750 | I38: =I34-I36 -> 1807166.7 | J38: =J34-J36 -> 903583.33 | K38: =K34-K36 -> 0 | L38: =L34-L36 -> 0 | M38: =M34-M36 -> 0 | ... O38: =O34-O36 -> 0
F40: 2021 | G40: 2022 | H40: 2023 | I40: 2024 | J40: 2025 | K40: 2026 | L40: 2027 | M40: 2028 | N40: 2029
D41: Opening Balance | E41: 0 | F41: =F34 -> 5421500 | G41: =F45 -> 4517916.7 | H41: =G45 -> 2710750 | I41: =H45 -> 903583.33 | J41: =I45 -> 0 | K41: =J45 -> 0 | L41: =K45 -> 0 | M41: =L45 -> 0 | N41: =M45 -> 0
D42: Interest | E42: 0 | F42: =E35+F35 -> 199511.2 | G42: =G35+H35 -> 533837.03 | H42: =I35+J35 -> 433177.85 | I42: =K35+L35 -> 92978.725 | J42: =L35+M35 -> 0 | K42: =M35+N35 -> 0 | L42: =N35+O35 -> 0 | M42: =O35+P35 -> 0 | N42: =P35+Q35 -> 0
D43: Principal PMT | E43: 0 | F43: =E36+F36 -> 903583.33 | G43: =G36+H36 -> 1807166.7 | H43: =I36+J36 -> 1807166.7 | I43: =K36+L36 -> 903583.33 | J43: =L36+M36 -> 0 | K43: =M36+N36 -> 0 | L43: =N36+O36 -> 0 | M43: =O36+P36 -> 0 | N43: =P36+Q36 -> 0
D44: Total PMT | E44: 0 | F44: =F42+F43 -> 1103094.5 | G44: =G42+G43 -> 2341003.7 | H44: =H42+H43 -> 2240344.5 | I44: =I42+I43 -> 996562.06 | J44: =J42+J43 -> 0 | K44: =K42+K43 -> 0 | L44: =L42+L43 -> 0 | M44: =M42+M43 -> 0 | N44: =N42+N43 -> 0
D45: Closing balance | E45: 0 | F45: =F41-F43 -> 4517916.7 | G45: =G41-G43 -> 2710750 | H45: =H41-H43 -> 903583.33 | I45: =I41-I43 -> 0 | J45: =J41-J43 -> 0 | K45: =K41-K43 -> 0 | L45: =L41-L43 -> 0 | M45: =M41-M43 -> 0 | N45: =N41-N43 -> 0
A47: In 2020, the Company obtained Islamic Long Term Financing Facility (ILTFF) of the State Bank of Pakistan for a period of 10 years through a musharaka agreement entered with financial institutions to finance its PVC-III expansion project. This is secured by way of hypothecation charge of present and future fixed assets of the Company (excluding land and building), to the extent of Rs. 2,437,500 which shall rank pari passu with the charges created in favour of the existing creditors.
A50: 18.3
A51: Principal Outstanding | B51: 2437500 | D51: Date | F51: 44896 | G51: =EDATE(F51,3) -> 44986 | H51: =EDATE(G51,3) -> 45078 | I51: =EDATE(H51,3) -> 45170 | J51: =EDATE(I51,3) -> 45261 | K51: =EDATE(J51,3) -> 45352 | L51: =EDATE(K51,3) -> 45444 | M51: =EDATE(L51,3) -> 45536 | N51: =EDATE(M51,3) -> 45627 | ... AU51: =EDATE(AT51,3) -> 48639
A52: Spread (annual) | B52: 0.012 | D52: Spread | F52: =$B$52 -> 0.012 | G52: =$B$52 -> 0.012 | H52: =$B$52 -> 0.012 | I52: =$B$52 -> 0.012 | J52: =$B$52 -> 0.012 | K52: =$B$52 -> 0.012 | L52: =$B$52 -> 0.012 | M52: =$B$52 -> 0.012 | ... AU52: =$B$52 -> 0.012
...

Sheet Depreciation schedule
B1: Assumptions | C1: 2019 | D1: 2020 | E1: 2021 | F1: 2022 | G1: 2023 | H1: 2024 | I1: 2025 | J1: 2026 | K1: 2027 | L1: 2028
A2: Property Plant and equipment | C2: =SUM(C3:C5) -> 31064266 | D2: =SUM(D3:D5) -> 36186640 | E2: =SUM(E3:E5) -> 36792644 | F2: =SUM(F3:F5) -> 41004218 | G2: =SUM(G3:G5) -> 44794643 | H2: =SUM(H3:H5) -> 50177016 | I2: =SUM(I3:I5) -> 52227831 | J2: =SUM(J3:J5) -> 54002526 | ... L2: =SUM(L3:L5) -> 61423110
A3: Operating assets | C3: 18304481 | D3: 19285257 | E3: 31388709 | F3: 34375626 | G3: 34567240 | H3: =H24+H44+H64+H86+H108+H130 -> 38184094 | I3: =I24+I44+I64+I86+I108+I130 -> 41009356 | J3: =J24+J44+J64+J86+J108+J130 -> 44477084 | K3: =K24+K44+K64+K86+K108+K130 -> 48906953 | L3: =L24+L44+L64+L86+L108+L130 -> 50373110
A4: Capital work in progress | C4: =SUM(C134:C140) -> 12695993 | D4: =SUM(D134:D140) -> 16837591 | E4: =SUM(E134:E140) -> 5185100 | F4: =SUM(F134:F140) -> 6416479 | G4: =SUM(G134:G140) -> 9981976 | H4: =SUM(H134:H140) -> 11832130 | I4: =SUM(I134:I140) -> 11038283 | J4: =SUM(J134:J140) -> 9321969.9 | ... L4: =SUM(L134:L140) -> 10851944
